2024-03-11 03:04:01,892 ERROR: Error: 500 Internal Server Error: The server encountered an internal error and was unable to complete your request. Either the server is overloaded or there is an error in the application.
2024-03-11 03:04:01,978 INFO: Request: GET /api/v1/highLightTitle.png b''
2024-03-11 03:04:01,978 ERROR: Error: 404 Not Found: The requested URL was not found on the server. If you entered the URL manually please check your spelling and try again.
2024-03-11 03:04:01,978 ERROR: Exception on /api/v1/highLightTitle.png [GET]
Traceback (most recent call last):
  File "/opt/homebrew/lib/python3.11/site-packages/flask/app.py", line 1484, in full_dispatch_request
    rv = self.dispatch_request()
         ^^^^^^^^^^^^^^^^^^^^^^^
  File "/opt/homebrew/lib/python3.11/site-packages/flask/app.py", line 1458, in dispatch_request
    self.raise_routing_exception(req)
  File "/opt/homebrew/lib/python3.11/site-packages/flask/app.py", line 1440, in raise_routing_exception
    raise request.routing_exception  # type: ignore
    ^^^^^^^^^^^^^^^^^^^^^^^^^^^^^^^
  File "/opt/homebrew/lib/python3.11/site-packages/flask/ctx.py", line 353, in match_request
    result = self.url_adapter.match(return_rule=True)  # type: ignore
             ^^^^^^^^^^^^^^^^^^^^^^^^^^^^^^^^^^^^^^^^
  File "/opt/homebrew/lib/python3.11/site-packages/werkzeug/routing/map.py", line 652, in match
    raise NotFound() from None
werkzeug.exceptions.NotFound: 404 Not Found: The requested URL was not found on the server. If you entered the URL manually please check your spelling and try again.

During handling of the above exception, another exception occurred:

Traceback (most recent call last):
  File "/opt/homebrew/lib/python3.11/site-packages/flask/app.py", line 2190, in wsgi_app
    response = self.full_dispatch_request()
               ^^^^^^^^^^^^^^^^^^^^^^^^^^^^
  File "/opt/homebrew/lib/python3.11/site-packages/flask/app.py", line 1486, in full_dispatch_request
    rv = self.handle_user_exception(e)
         ^^^^^^^^^^^^^^^^^^^^^^^^^^^^^
  File "/opt/homebrew/lib/python3.11/site-packages/flask/app.py", line 1341, in handle_user_exception
    return self.handle_http_exception(e)
           ^^^^^^^^^^^^^^^^^^^^^^^^^^^^^
  File "/opt/homebrew/lib/python3.11/site-packages/flask/app.py", line 1281, in handle_http_exception
    return self.ensure_sync(handler)(e)
           ^^^^^^^^^^^^^^^^^^^^^^^^^^^^
  File "/Users/liozakirav/Documents/Projects/WearCastAI/backend/utils/logger.py", line 22, in handle_exception
    return jsonify({'error': 'An error occurred'}), 500
           ^^^^^^^
NameError: name 'jsonify' is not defined
2024-03-11 03:04:01,981 ERROR: Error: 500 Internal Server Error: The server encountered an internal error and was unable to complete your request. Either the server is overloaded or there is an error in the application.
2024-03-11 03:07:43,719 INFO: Request: GET /api/v1/weather-by-coordinates b''
2024-03-11 03:07:43,888 ERROR: Error: 404 Not Found: Failed to fetch weather data
2024-03-11 03:07:43,889 ERROR: Exception on /api/v1/weather-by-coordinates [GET]
Traceback (most recent call last):
  File "/Users/liozakirav/Documents/Projects/WearCastAI/backend/venv/lib/python3.11/site-packages/flask/app.py", line 870, in full_dispatch_request
    rv = self.dispatch_request()
         ^^^^^^^^^^^^^^^^^^^^^^^
  File "/Users/liozakirav/Documents/Projects/WearCastAI/backend/venv/lib/python3.11/site-packages/flask/app.py", line 855, in dispatch_request
    return self.ensure_sync(self.view_functions[rule.endpoint])(**view_args)  # type: ignore[no-any-return]
           ^^^^^^^^^^^^^^^^^^^^^^^^^^^^^^^^^^^^^^^^^^^^^^^^^^^^^^^^^^^^^^^^^
  File "/Users/liozakirav/Documents/Projects/WearCastAI/backend/controllers/weather_controller.py", line 18, in get_weather_by_coordinates
    abort(404, 'Failed to fetch weather data')
  File "/Users/liozakirav/Documents/Projects/WearCastAI/backend/venv/lib/python3.11/site-packages/flask/helpers.py", line 272, in abort
    current_app.aborter(code, *args, **kwargs)
  File "/Users/liozakirav/Documents/Projects/WearCastAI/backend/venv/lib/python3.11/site-packages/werkzeug/exceptions.py", line 861, in __call__
    raise self.mapping[code](*args, **kwargs)
werkzeug.exceptions.NotFound: 404 Not Found: Failed to fetch weather data

During handling of the above exception, another exception occurred:

Traceback (most recent call last):
  File "/Users/liozakirav/Documents/Projects/WearCastAI/backend/venv/lib/python3.11/site-packages/flask/app.py", line 1463, in wsgi_app
    response = self.full_dispatch_request()
               ^^^^^^^^^^^^^^^^^^^^^^^^^^^^
  File "/Users/liozakirav/Documents/Projects/WearCastAI/backend/venv/lib/python3.11/site-packages/flask/app.py", line 872, in full_dispatch_request
    rv = self.handle_user_exception(e)
         ^^^^^^^^^^^^^^^^^^^^^^^^^^^^^
  File "/Users/liozakirav/Documents/Projects/WearCastAI/backend/venv/lib/python3.11/site-packages/flask/app.py", line 755, in handle_user_exception
    return self.handle_http_exception(e)
           ^^^^^^^^^^^^^^^^^^^^^^^^^^^^^
  File "/Users/liozakirav/Documents/Projects/WearCastAI/backend/venv/lib/python3.11/site-packages/flask/app.py", line 730, in handle_http_exception
    return self.ensure_sync(handler)(e)  # type: ignore[no-any-return]
           ^^^^^^^^^^^^^^^^^^^^^^^^^^^^
  File "/Users/liozakirav/Documents/Projects/WearCastAI/backend/utils/logger.py", line 22, in handle_exception
    return jsonify({'error': 'An error occurred'}), 500
           ^^^^^^^
NameError: name 'jsonify' is not defined
2024-03-11 03:07:43,902 ERROR: Error: 500 Internal Server Error: The server encountered an internal error and was unable to complete your request. Either the server is overloaded or there is an error in the application.
2024-03-11 03:07:44,151 INFO: Request: GET /favicon.ico b''
2024-03-11 03:07:44,151 ERROR: Error: 404 Not Found: The requested URL was not found on the server. If you entered the URL manually please check your spelling and try again.
2024-03-11 03:07:44,152 ERROR: Exception on /favicon.ico [GET]
Traceback (most recent call last):
  File "/Users/liozakirav/Documents/Projects/WearCastAI/backend/venv/lib/python3.11/site-packages/flask/app.py", line 870, in full_dispatch_request
    rv = self.dispatch_request()
         ^^^^^^^^^^^^^^^^^^^^^^^
  File "/Users/liozakirav/Documents/Projects/WearCastAI/backend/venv/lib/python3.11/site-packages/flask/app.py", line 844, in dispatch_request
    self.raise_routing_exception(req)
  File "/Users/liozakirav/Documents/Projects/WearCastAI/backend/venv/lib/python3.11/site-packages/flask/app.py", line 453, in raise_routing_exception
    raise request.routing_exception  # type: ignore[misc]
    ^^^^^^^^^^^^^^^^^^^^^^^^^^^^^^^
  File "/Users/liozakirav/Documents/Projects/WearCastAI/backend/venv/lib/python3.11/site-packages/flask/ctx.py", line 362, in match_request
    result = self.url_adapter.match(return_rule=True)  # type: ignore
             ^^^^^^^^^^^^^^^^^^^^^^^^^^^^^^^^^^^^^^^^
  File "/Users/liozakirav/Documents/Projects/WearCastAI/backend/venv/lib/python3.11/site-packages/werkzeug/routing/map.py", line 624, in match
    raise NotFound() from None
werkzeug.exceptions.NotFound: 404 Not Found: The requested URL was not found on the server. If you entered the URL manually please check your spelling and try again.

During handling of the above exception, another exception occurred:

Traceback (most recent call last):
  File "/Users/liozakirav/Documents/Projects/WearCastAI/backend/venv/lib/python3.11/site-packages/flask/app.py", line 1463, in wsgi_app
    response = self.full_dispatch_request()
               ^^^^^^^^^^^^^^^^^^^^^^^^^^^^
  File "/Users/liozakirav/Documents/Projects/WearCastAI/backend/venv/lib/python3.11/site-packages/flask/app.py", line 872, in full_dispatch_request
    rv = self.handle_user_exception(e)
         ^^^^^^^^^^^^^^^^^^^^^^^^^^^^^
  File "/Users/liozakirav/Documents/Projects/WearCastAI/backend/venv/lib/python3.11/site-packages/flask/app.py", line 755, in handle_user_exception
    return self.handle_http_exception(e)
           ^^^^^^^^^^^^^^^^^^^^^^^^^^^^^
  File "/Users/liozakirav/Documents/Projects/WearCastAI/backend/venv/lib/python3.11/site-packages/flask/app.py", line 730, in handle_http_exception
    return self.ensure_sync(handler)(e)  # type: ignore[no-any-return]
           ^^^^^^^^^^^^^^^^^^^^^^^^^^^^
  File "/Users/liozakirav/Documents/Projects/WearCastAI/backend/utils/logger.py", line 22, in handle_exception
    return jsonify({'error': 'An error occurred'}), 500
           ^^^^^^^
NameError: name 'jsonify' is not defined
2024-03-11 03:07:44,156 ERROR: Error: 500 Internal Server Error: The server encountered an internal error and was unable to complete your request. Either the server is overloaded or there is an error in the application.
2024-03-11 03:07:44,244 INFO: Request: GET /api/v1/highLightTitle.png b''
2024-03-11 03:07:44,244 ERROR: Error: 404 Not Found: The requested URL was not found on the server. If you entered the URL manually please check your spelling and try again.
